(dp1
S'output'
p2
S'<class \'_mysql_exceptions.OperationalError\'> (1050, "Table \'SHITDATA\' already exists")'
p3
sS'layer'
p4
S'/opt/web2py/applications/know_your_world/models/db.py'
p5
sS'code'
p6
S"db = DAL('mysql://root:wtfcall911@localhost/factbook')\ndb.define_table('SHITDATA',\n   Field('country_id'),\n   Field('country'),\n   Field('data'))\n\ndb.SHITDATA.country.requires = IS_NOT_IN_DB(db,db.SHITDATA.country)\ndb.SHITDATA.country_id.requires = IS_NOT_IN_DB(db,db.SHITDATA.country_id)\ndb.SHITDATA.country.require = IS_NOT_EMPTY()\ndb.SHITDATA.country_id.require = IS_NOT_EMPTY() \ndb.SHITDATA.id.require = IS_NOT_EMPTY()\ndb.SHITDATA.data.require = IS_LENGTH(9999999999999)\n"
p7
sS'snapshot'
p8
(dp9
sS'traceback'
p10
S'Traceback (most recent call last):\n  File "/opt/web2py/gluon/restricted.py", line 212, in restricted\n    exec ccode in environment\n  File "/opt/web2py/applications/know_your_world/models/db.py", line 5, in <module>\n    Field(\'data\'))\n  File "/opt/web2py/gluon/dal.py", line 7644, in define_table\n    table = self.lazy_define_table(tablename,*fields,**args)\n  File "/opt/web2py/gluon/dal.py", line 7681, in lazy_define_table\n    polymodel=polymodel)\n  File "/opt/web2py/gluon/dal.py", line 960, in create_table\n    self.create_sequence_and_triggers(query,table)\n  File "/opt/web2py/gluon/dal.py", line 1741, in create_sequence_and_triggers\n    self.execute(query)\n  File "/opt/web2py/gluon/dal.py", line 1756, in execute\n    return self.log_execute(*a, **b)\n  File "/opt/web2py/gluon/dal.py", line 1750, in log_execute\n    ret = self.cursor.execute(*a, **b)\n  File "/usr/lib/python2.7/dist-packages/MySQLdb/cursors.py", line 174, in execute\n    self.errorhandler(self, exc, value)\n  File "/usr/lib/python2.7/dist-packages/MySQLdb/connections.py", line 36, in defaulterrorhandler\n    raise errorclass, errorvalue\nOperationalError: (1050, "Table \'SHITDATA\' already exists")\n'
p11
s.